# 错误处理

React提供了两个与'错误处理'相关的API

- getDerivedStateFromError： 静态方法打，当错误发生后，提供一个机会渲染 fallback UI
- componentDidCatch: 组件实例方法，当错误发生后，提供一个机会记录错误信息  

通过这两个API，可以在Class Component中实现错误边界，（Error Boundaries）。在Error Boundaries的子孙组件中发生的所有'react 工作流程内的错误'都会被 ErrorBoundaries 捕获。React 工作流程指的是:

- render 阶段
- commit 阶段

**有四类错误不会被Error Boundaries捕获**：

1. 事件回调中的错误  
点击触发 handleClick事件，抛出的错误不会被 Error Boundaries 捕获，如下:

```jsx
const B = () =>{
    const handleClick = ()=>{
        throw new Error('error ')
    }
    return <div onClick={handleClick}>Hello</div>
}
```

从两个角度来分析:
    - 从‘源码执行流程’角度看，事件回调不属于React工作流程，所以不会被捕获
    - 从‘设计动机’角度看， Error Boundaries 的设计目的是‘避免错误发生导致UI显示不完全’。只有 commit阶段才会造成 UI改变(具体来说是 Mutation阶段)，所以事件回调内抛出的错误不会导致UI改变。

2. 异步代码，比如 `setTimeout, requestAnimationFrame`的回调
异步代码不属于 react工作流程，所以不会被捕获  

3. Server side rendering  
SSR不属于 react工作流程，所以不会被捕获

4. 在Error Boundaries所属的Component 内发生的错误  
Error Boundaries 只会捕获子孙组件发生的React 工作流程的错误。

**Error Boundaries如何捕获React 工作流程内的错误**  
三个阶段

- 捕获错误
- 构造callback
- 执行callback  

## 捕获错误

render阶段的核心代码如下，发生的错误会被捕获并交由 handleError处理:  

```jsx
do {
    try{
        // 对于并发更新则是 workLoopConcurrnet
        workLoopSync()
        break;
    }catch(error){
        handleError(root, error)
    }
    
} while(true)
```

commit 阶段包含很多工作，比如:

- 执行三个子阶段的commitXXXEffectsOnFiber;
- 执行componentDidMount/Update
- 绑定/解绑 ref
- 执行 useEffect/useLayoutEffect callback与 destory
发生的错误会被捕获并交由 captureCommitPhaseError处理:

```jsx
try{
    // 省略执行某项工作
}catch(error){
    captureCommitPhaseError(fiber,fiber,return, error)
}
```

## 构造callback

即使不存在 Error Boundaries，工作流程中的错误也已经被被React 捕获，接下来正确的逻辑是:

- 如果存在Error Boundaries，执行对于方法
- 抛出React错误提示信息，包括提示语和错误堆栈信息
- 如果不存在Error Boundaries，抛出'未捕获的错误'  

不管是 handleError 还是 captureCommitPhaseError 都会从‘发生错误的fiberNode的父fiberNode’开始，逐层向上遍历，寻找最近的Error Boundaries，一旦找到，就会执行 createClassErrorUpdate方法，构造如下两个callback：

- 用于‘执行Error Boundaries API’的callback
- 用于'抛出React 提示信息'的callback  

```js
function createClassErrorUpdate(/*省略参数*/) {
    // 逻辑有删减
    if(typeof getDerivedStateFromError ==='function'){
        // 用于执行 getDerivedStateFromError 的callback
        update.payload=()=>{
            return getDerivedStateFromError(error)
        }
        // 用于抛出React提示信息的 callback
        update.callback=()=>{
            logCaptureError(fiber,errorInfo)
        }
    }
    if(inst !==null && typeof inst.componentDidCatch === 'function'){
        // 用于执行 componentDidCatch的callback
        update.callback = function callback(){
            this.componentDidCatch(error)
        }
    }
    return update;
}
```

如果没有找到 Error Boundaries，则继续向上遍历直到 HostRootFiber,并执行 createRootErrorUpdate构造callback,在callback内抛出‘未捕获的错误’和‘react的提示信息’

```js
function createRootErrorUpdate(/*省略参数*/) {
    // 省略代码
    // 用于抛出‘未捕获的错误’和‘react提示信息的’callback
    update.callback = ()=>{
        onUncaughtError(error)
        logCapturedError(fiber,errorInfo)
    }
    return update
}
```

## 执行callback

两个执行用户自定义callback的api：

- 对于 ClassComponent， this.setState(newState,callback)中newState和callback参数都能传递‘函数类型参数’作为callback  
对于Error Boundaries，类似于触发了一次如下所示的更新，这也是Error Boundaries属于Class Component特性的原因:

```js
this.setState(()=>{
    // 用于执行 getDerivedStateFromError 的callback
},()=>{
    // 用于执行 componentDidCatch的callback
    // 以及用于抛出React 提示信息的 callback
})
```

- 对于HostRoot，执行 ReactDOM.render(element,container,callback)时，第三个参数 callback接收一个回调函数作为'commit阶段完成后执行的回调函数'  

对于‘不存在Error Boundaries’情况下发生的流程内部错误，类似于执行了如下函数:

```js
ReactDOM.render(element,container,()=>{
    // 用于抛出‘未捕获错误’和‘React提示信息’的callback
})
```

这些callback会在适当的时机执行，完成‘错误处理’的逻辑。
