# 错误边界

React部分组件的错误不应该导致整个应用崩溃，为了解决这个问题，React16引入了错误边界

## 使用方法

React组件在内部定义了`getDerivedStateFromError`或者`componentDidCatch`，它就是一个错误边界。`getDerviedStateFromError`和`componentDidCatch`的区别是前者返回一个state用户展示降级UI，后者记录具体的错误信息，它只能用于class组件

```javascript
import react from 'react'

class ErrorBoundary extends react.Component{
    constructor(props){
        super(props)
        this.state={
            hasError:false
        }
    }

    // 控制state，显示降级UI
    static getDerivedStateFromError(){
        return {hasError:true}
    }

    // 展示错误信息，以及具体错误,一般会在这里讲错误日志上报到服务端，方便后续分析
    componentDidCatch(err,info){
        console.log(err,info)
    }

    render(){
        if(this.state.hasError){
            return <>Sorry, has Error</>
        }
        return this.props.children
    }
}

// App.jsx
import React from "react"
import ErrorBoundary from "./components/ErrorBoundary"
import ComponentA from "./components/ComponentA"
export class App extends React.Component{
  render(){
    return (
      <ErrorBoundary>
        <ComponentA></ComponentA>
      </ErrorBoundary>
    )
  }
}
```

## tips: 
> 错误边界无法捕获自身的错误，也无法捕获事件处理，异步代码（setTimeout, requestAnimationFrame），服务端渲染的错误


# Suspense
允许在子组件完成加载前展示后备方案。
一般是和 React.lazy 结合用，用来加载一些异步组件，当然也可以单独使用。
### 使用场景
- 支持 Suspense 的框架如 Relay 和 Next.js。
- 使用 lazy 懒加载组件代码。
- 使用 use 读取 Promise 的值。

> Suspense 无法 检测在 Effect 或事件处理程序中获取数据的情况

promise 初始状态展示 fallback，promise 改变状态后展示子组件。

```javascript
import { Suspense } from "react";

let data, promise;
function fetchData() {
  if (data) return data;
  promise = new Promise(resolve => {
    setTimeout(() => {
      data = '取到的数据'
      resolve()
    }, 2000)
  })
  throw promise;
}

function Content() {
  const data = fetchData();
  return <p>{data}</p>
}

export default function App() {
  return (
    <Suspense fallback={'loading data'}>
      <Content />
    </Suspense>
  )
}
```

它的底层就是throw一个Promise出来，然后react会捕捉这个promise，交给最近的suspense组件来处理。promise 初始状态展示 fallback，promise 改变状态后展示子组件

类似的，ErrorBoundary 也是这种处理方式，只不过捕获的是 throw 的 error。且ErrorBoundary与Suspense的捕获不相互干扰。

ErrorBoundary 只能是 class 组件的形式，通过 getDerivedStateFromError 方法来接收错误修改 state，以及 componentDidCatch 来打印错误日志。
在function 组件中想要使用errorBoundary捕获错误信息，可以使用`react-error-boundary`包。


自己写 throw promise 来触发 Suspense 还是很麻烦的，一般我们都不用这个，而是自己写个 loading 的 state 来标识。

不过当你用 next.js、jotai 等框架的时候，因为内部做了 throw promise 的封装，就可以直接用 Suspense 了。

此外，react 有一个 use 的 hook，可以接收 promise，在 pending 的时候触发 Suspense，在 reject 的时候触发 ErrorBoundary，底层原理就是 throw error 和 promise。

这个 hook 还在实验阶段，等正式发布之后，估计代码里就会有大量 Suspense 了。
